scripts/test_case7.txt
40
0 o
1 o
2 o
3 o
4 o
5 o
6 o
7 o
8 o
9 o
10 o
11 o
12 o
13 o
14 o
15 o
16 o
17 o
18 o
19 o
20 o
21 o
22 o
23 o
24 o
25 o
26 o
27 o
28 o
29 o
30 o
31 o
32 o
33 o
34 o
35 o
36 o
37 o
38 o
39 o
.
39 B 90561840 AAPL 95683 7575
39 C 90561840
38 S 73606232 AAPL 3686 9712
39 C 90561840
31 S 88081413 GOOG 20882 1528
38 C 73606232
39 C 90561840
38 C 73606232
38 S 79586006 AMZN 88550 6440
38 C 73606232
38 C 79586006
39 S 87162596 AMZN 14426 3409
38 S 72315622 AAPL 9854 6869
39 C 87162596
37 B 58202792 MSFT 40048 2934
37 B 53268740 GOOG 61899 6174
38 B 62354884 MSFT 45194 143
38 C 79586006
38 S 60540047 GOOG 93994 2528
39 S 14456737 MSFT 41654 1318
37 C 58202792
38 S 36378739 GOOG 71856 6190
39 C 87162596
39 C 14456737
38 C 62354884
39 S 96782699 AAPL 8924 3614
39 C 87162596
38 C 36378739
39 S 42474567 AMZN 57944 6481
39 S 40527762 AAPL 31649 4430
38 B 7110710 MSFT 58830 5368
38 C 79586006
38 C 36378739
38 C 36378739
39 S 36578865 AAPL 71576 992
39 B 60377205 MSFT 29794 2915
39 S 68780283 MSFT 60899 9356
39 C 90561840
38 B 40685217 AMZN 12363 7746
39 S 22048733 AMZN 41123 2784
38 S 66450336 AMZN 32831 1282
39 C 96782699
39 C 96782699
38 B 58200230 GOOG 96140 1927
38 S 10121649 AMZN 24846 3622
37 S 40084154 AMZN 87080 2952
38 B 10983134 AAPL 81353 8967
39 C 14456737
39 B 43037593 AAPL 45781 4038
37 B 20042486 GOOG 97338 2416
37 C 53268740
39 C 36578865
39 C 40527762
38 C 58200230
38 S 14548786 AMZN 67566 6934
39 C 96782699
39 B 85555673 GOOG 8936 8345
39 C 87162596
38 C 7110710
39 S 52739847 AAPL 3806 9032
39 S 64927120 AAPL 38216 1483
39 B 24434423 AMZN 66198 4377
38 C 79586006
39 C 68780283
37 S 4002044 AMZN 11688 9731
37 C 4002044
36 S 20282697 GOOG 9452 9657
34 B 95972537 AMZN 89737 7912
38 S 47161825 AMZN 1253 387
38 C 36378739
39 B 94995040 GOOG 61639 770
34 B 47118269 GOOG 15605 8867
38 C 66450336
39 B 8864046 AAPL 13207 5366
39 S 83911178 AAPL 9282 7821
36 B 51404043 AMZN 67981 4591
37 B 21488402 GOOG 15119 4418
37 B 32521554 AMZN 44593 5551
39 B 84914442 GOOG 16538 9417
39 B 289602 MSFT 3666 8909
38 B 40723595 AMZN 79690 8791
39 C 36578865
38 C 40723595
36 S 78504023 AAPL 59733 1017
39 S 38017581 AAPL 49806 4090
39 B 12386794 AMZN 12459 2699
39 B 35071093 MSFT 99202 4158
39 C 14456737
39 S 22390696 AMZN 22241 9573
38 C 79586006
38 C 58200230
38 B 53020038 AMZN 21104 1749
39 B 87661828 AMZN 19438 1397
38 C 10983134
39 C 84914442
36 B 38352473 MSFT 6462 6105
39 C 90561840
37 B 27675627 MSFT 10110 4821
39 C 60377205
37 B 19035 AMZN 33546 8207
39 B 94734825 GOOG 22302 5302
37 S 70314248 AMZN 97293 9247
39 S 78058354 AAPL 27745 7265
38 C 7110710
38 C 7110710
39 B 986334 AMZN 15144 73
38 B 65497384 AMZN 15130 9640
39 S 27291338 AMZN 4519 4100
36 B 43050486 AAPL 73925 1745
36 B 33867745 GOOG 23769 7161
35 S 27949868 GOOG 70929 5122
39 C 14456737
38 S 5236087 MSFT 46162 3579
39 B 44418451 AAPL 52760 258
38 B 66096737 GOOG 27692 3710
37 B 89368457 AMZN 8565 3849
39 C 22048733
39 S 74061578 AAPL 98706 6859
36 B 23364981 AAPL 72995 4866
38 B 97003261 MSFT 93125 3929
38 C 5236087
37 B 48690033 MSFT 55318 3689
39 S 2874349 GOOG 86132 6169
39 B 12368298 AMZN 76250 6627
38 B 42966976 GOOG 36941 5778
39 S 99980091 GOOG 60516 3068
38 S 1005291 GOOG 81438 1308
39 S 22134016 GOOG 35254 9373
39 S 90810111 MSFT 39798 6594
38 C 1005291
32 B 79665640 MSFT 23012 2505
38 S 98413433 AAPL 30550 524
39 S 18707332 MSFT 69764 9295
39 S 50277773 GOOG 3225 9110
39 C 83911178
36 C 38352473
39 C 12386794
38 C 40685217
39 C 40527762
34 B 49641222 AAPL 10449 4176
38 S 14166109 AMZN 17634 5539
39 C 289602
36 B 98930577 AAPL 50364 7362
39 S 27555849 MSFT 93230 103
39 B 91298687 MSFT 56099 8153
39 B 33420904 AAPL 83536 1654
39 S 22266380 AAPL 8833 1599
39 S 80925541 AAPL 45198 4756
39 S 10480778 AAPL 7310 1334
38 C 10121649
35 B 75194672 AMZN 87248 1754
39 S 44996325 GOOG 98111 7651
39 S 92429549 AMZN 10409 9817
38 B 84208967 GOOG 2408 8540
35 S 9897979 AMZN 13306 146
37 B 98678009 GOOG 29676 3249
39 S 1687235 AMZN 47774 7606
38 C 1005291
34 B 90521611 MSFT 15279 8995
39 B 17844183 AMZN 48591 9251
39 C 50277773
39 B 12197314 AMZN 77804 3633
33 B 20437007 GOOG 94543 4182
39 S 91394057 GOOG 55944 2602
39 B 10792372 AAPL 49237 7924
39 B 75164177 AMZN 86221 5307
39 C 99980091
38 S 77840441 GOOG 23201 1643
38 S 54814977 MSFT 45867 9711
37 S 20510637 AAPL 82658 3780
39 B 24918126 AMZN 7068 8445
38 C 42966976
38 B 60171042 AMZN 46222 1904
39 S 28854422 AMZN 19072 6411
39 S 448839 AMZN 24039 7416
39 B 94574268 MSFT 27504 347
39 S 7999084 GOOG 95232 9852
38 C 97003261
39 B 53246903 MSFT 9375 722
39 S 84781184 MSFT 21430 9420
39 C 22266380
38 S 25526315 AAPL 33610 6648
39 B 41506051 MSFT 66416 760
39 C 28854422
37 B 60219338 AMZN 39777 1
38 S 59827274 GOOG 34518 7820
37 S 84642760 AMZN 50620 8276
39 C 22390696
38 C 72315622
38 C 58200230
38 S 7366697 AAPL 55498 7847
39 C 40527762
39 B 30910101 MSFT 80847 5457
39 C 68780283
39 C 91298687
39 C 87162596
39 C 91394057
39 B 32393407 MSFT 5054 489
38 C 14548786
37 S 43928851 AMZN 50085 9659
36 B 59396150 MSFT 11748 2051
39 S 71552832 AMZN 69040 7896
38 S 84103604 AMZN 96246 3693
36 S 82619954 GOOG 16711 7023
37 S 54171535 AAPL 83951 5650
36 C 82619954
35 S 79141006 MSFT 62335 2444
37 S 58255773 AMZN 27118 8596
38 S 27007663 AMZN 13564 3431
38 C 59827274
38 S 54320561 MSFT 57130 1065
35 S 36976871 GOOG 69741 6437
38 S 86839553 MSFT 27510 8235
38 B 88051758 AMZN 80569 4507
38 C 25526315
35 C 75194672
38 S 94572923 AAPL 13281 9839
38 S 18834288 AAPL 70659 8543
36 B 55663073 AMZN 51643 2084
37 B 29558554 AMZN 41416 9070
37 S 19696923 MSFT 82917 9972
35 B 49402813 AMZN 65981 1261
37 C 4002044
38 S 45932765 AMZN 95783 1642
37 B 69926804 MSFT 98663 3072
38 C 79586006
38 C 25526315
37 S 94785356 MSFT 4073 3854
36 C 20282697
38 B 80216082 GOOG 21936 5268
38 S 81483738 MSFT 61912 4918
38 S 56684899 MSFT 48888 6586
34 S 64733340 GOOG 11381 2481
37 S 59546967 GOOG 76987 5142
38 S 68989916 AMZN 66939 2435
32 S 30284290 AAPL 89220 4775
38 S 51358294 AMZN 88433 5473
38 C 42966976
38 B 72000953 MSFT 22149 1695
37 S 26563424 MSFT 73223 4619
38 S 44178358 GOOG 41221 7140
35 S 30924320 MSFT 92720 6059
34 B 87124725 AMZN 26420 7533
34 S 79396523 AMZN 71254 5342
37 B 29101441 GOOG 1844 9886
38 B 76940702 GOOG 55320 3085
28 B 24377087 AAPL 6650 8937
36 C 59396150
38 B 89851694 GOOG 55215 2327
38 S 78361629 MSFT 67867 7339
38 B 87018846 MSFT 66747 4600
38 S 16935435 MSFT 41867 5587
37 S 97191807 AAPL 84916 1839
38 S 24488927 AMZN 80223 2871
38 C 36378739
37 S 82498077 AAPL 51461 4415
37 S 55488778 AAPL 69471 3932
38 B 72611352 MSFT 10858 9155
36 S 2509533 MSFT 45884 7133
38 S 98682192 AMZN 76519 9989
38 B 97457465 AMZN 92519 8130
34 B 72997007 GOOG 94014 8111
37 B 59704468 GOOG 83113 9841
37 B 1052042 AMZN 34433 6654
36 C 38352473
37 S 45767365 MSFT 91187 9339
38 B 32278585 AAPL 76992 8870
35 B 92159371 AAPL 55301 720
38 B 62341220 AAPL 94884 3917
37 C 82498077
38 B 20789400 AMZN 37546 6269
37 B 93246752 AMZN 30321 4494
38 S 98724192 GOOG 12399 7756
37 B 79137878 AMZN 81677 3636
37 B 18252477 GOOG 54321 903
38 S 41983436 AAPL 41809 273
37 S 90675321 AMZN 27598 8277
37 B 95692186 AAPL 59613 6806
38 S 25348370 AMZN 51403 2182
38 B 7561682 MSFT 25863 9031
36 B 99807109 MSFT 96225 8674
37 B 45928456 AAPL 59099 9130
37 S 40349388 MSFT 68951 4296
36 C 82619954
37 B 31364884 MSFT 30638 3478
35 S 25644086 MSFT 96777 1755
36 C 99807109
33 B 53970067 AMZN 34803 1043
37 C 48690033
36 B 62758049 GOOG 26415 1686
37 B 52975832 MSFT 78125 7185
37 S 534860 AMZN 88844 8141
37 B 58247636 GOOG 13499 3927
37 B 85749193 GOOG 70550 8521
36 C 51404043
37 C 93246752
37 C 70314248
34 S 50302411 AMZN 18855 6741
37 S 40597174 MSFT 19285 4752
34 S 1264921 AMZN 85575 8662
37 S 84188374 GOOG 45650 1144
36 C 78504023
37 C 45928456
37 C 58255773
37 S 70719660 AMZN 32703 5020
37 C 89368457
35 S 84247808 AMZN 76790 7605
34 B 7961513 GOOG 10218 174
35 S 23589147 AAPL 30311 4635
36 C 82619954
36 C 98930577
37 B 4880812 AAPL 63765 562
37 S 67828294 AAPL 65504 1489
37 S 93839701 AMZN 73372 5529
36 S 17106822 GOOG 5448 2772
