scripts/test_case8.txt
40
0 o
1 o
2 o
3 o
4 o
5 o
6 o
7 o
8 o
9 o
10 o
11 o
12 o
13 o
14 o
15 o
16 o
17 o
18 o
19 o
20 o
21 o
22 o
23 o
24 o
25 o
26 o
27 o
28 o
29 o
30 o
31 o
32 o
33 o
34 o
35 o
36 o
37 o
38 o
39 o
.
36 B 74665268 GOOG 30556 4725
39 B 89754751 AAPL 56485 4122
39 B 66020617 AAPL 8963 1150
34 S 23107766 GOOG 68389 1205
35 B 83837991 GOOG 26125 2989
39 B 77827578 AAPL 41073 9910
37 B 72028411 MSFT 39531 5003
39 C 77827578
39 S 57620873 AMZN 78567 2065
39 S 65635373 AAPL 79083 662
39 S 23212654 MSFT 91435 1185
37 S 52620774 AMZN 70301 5994
39 S 92399791 MSFT 18781 2171
39 S 80968130 MSFT 15612 1280
39 S 10902500 GOOG 42015 3478
39 B 54181844 MSFT 31994 9586
37 C 72028411
39 C 54181844
39 B 79364347 GOOG 9045 1231
35 S 79274038 MSFT 41580 6071
35 C 79274038
38 S 25247429 MSFT 19523 7169
39 C 77827578
39 B 79083275 MSFT 75938 7867
38 C 25247429
37 S 26455159 AMZN 80788 2380
38 S 38213986 AAPL 58866 8029
39 C 89754751
39 S 71259664 AAPL 3805 6891
39 S 54941465 AMZN 25008 5858
39 B 40407127 GOOG 41392 204
39 B 23906695 MSFT 91501 9328
39 B 27492560 MSFT 28564 4444
39 C 89754751
39 C 77827578
39 S 69568738 AAPL 23299 646
39 C 66020617
38 B 22419743 AMZN 94790 191
38 C 22419743
38 B 86922514 AAPL 48740 4901
35 C 79274038
39 B 4415346 AMZN 42040 2168
36 S 16765148 MSFT 74549 6016
39 B 76884492 MSFT 7150 5046
36 B 80002238 GOOG 5591 5372
38 C 22419743
39 B 49722903 AMZN 67738 3633
36 S 16377066 MSFT 44903 1076
39 B 18271069 GOOG 9159 714
39 C 27492560
36 C 16765148
39 C 65635373
39 C 54181844
36 S 20092468 AMZN 92111 9071
39 B 53355908 AAPL 36537 4937
34 C 23107766
38 B 57201475 GOOG 18494 9957
39 B 79949165 AAPL 81800 2464
33 S 95967056 MSFT 51537 4953
39 C 92399791
38 C 57201475
39 B 11716145 AAPL 70238 9242
36 C 20092468
37 S 97553118 MSFT 91287 1386
39 S 86816315 AMZN 52481 33
38 S 49303804 MSFT 58157 6819
39 B 76974948 GOOG 69276 8630
38 S 40711141 MSFT 98366 4104
39 C 53355908
39 B 56414962 GOOG 28875 1637
39 B 71570554 AAPL 9983 6751
39 C 92399791
38 C 57201475
39 B 40822748 AAPL 75267 7152
36 C 74665268
39 S 68250466 GOOG 40661 7206
39 C 54941465
38 B 32376002 AMZN 58862 3878
38 C 49303804
39 C 79083275
37 C 52620774
38 B 32740957 AAPL 6571 2642
38 S 88416671 MSFT 52097 5447
38 C 32740957
37 B 41256140 MSFT 81369 6333
39 S 26556526 AAPL 22961 3110
39 B 43339804 AAPL 5911 3487
39 B 87415800 GOOG 25016 4601
39 B 8820344 MSFT 26048 4808
37 C 41256140
36 S 79804523 AMZN 89722 1274
39 S 77501489 MSFT 8560 5839
38 B 79062222 MSFT 76327 9752
36 B 76415819 GOOG 71409 8786
37 S 49559359 AAPL 56970 5343
37 B 685956 AAPL 37450 7720
39 B 91102705 AAPL 77182 8700
38 S 16938589 AMZN 64966 2782
35 B 74857456 GOOG 25453 2562
37 C 685956
33 S 19358519 AAPL 41575 2284
39 S 63985672 AMZN 48511 8975
39 C 54181844
37 C 97553118
39 C 40822748
35 S 20836108 AAPL 15449 8714
39 B 5270954 MSFT 85923 6031
38 C 88416671
37 S 80690993 MSFT 16342 9607
39 C 27492560
36 S 61612620 AAPL 52646 7042
39 S 25435593 AMZN 61404 7192
38 S 46308837 AMZN 72507 7655
39 B 19420930 AAPL 74501 2065
33 S 23746215 AMZN 13654 709
36 S 39166909 MSFT 17654 8300
39 C 26556526
39 C 23212654
36 B 41392090 AAPL 89422 5734
39 B 67042869 GOOG 92626 2472
38 C 32740957
39 B 124870 AAPL 18425 1044
38 B 79900673 GOOG 20844 4947
38 C 16938589
37 B 35244227 AAPL 74762 3954
39 C 63985672
39 S 74592288 AMZN 85936 5903
38 B 85404274 AAPL 82465 4769
39 S 65526582 AMZN 81648 5167
39 C 66020617
37 S 76249563 GOOG 51697 2056
37 C 35244227
38 C 46308837
39 S 11136564 MSFT 93899 8690
38 S 83021229 GOOG 99235 5125
37 B 77130868 MSFT 91444 2649
36 C 76415819
38 S 26928089 GOOG 38762 7825
38 S 86168286 MSFT 76867 6009
39 S 25807524 GOOG 54497 898
39 S 70384278 MSFT 91761 7371
39 C 25807524
38 C 79062222
39 B 7598230 AAPL 20761 8881
39 C 86816315
34 C 23107766
39 S 24978282 GOOG 99151 6587
39 B 87376275 GOOG 90840 8698
39 B 46675665 AAPL 54808 599
36 S 4432272 AMZN 58626 9214
36 S 64601912 MSFT 51489 752
39 S 65520234 MSFT 69276 4149
39 S 24601418 GOOG 15918 6595
39 S 28455470 AMZN 37875 8986
39 S 82886602 AMZN 22738 1820
39 C 25807524
37 B 64193228 AMZN 3705 6266
38 C 16938589
39 B 95570861 GOOG 68871 1424
38 C 79062222
35 S 8217047 MSFT 75335 4253
39 B 66853468 AAPL 6819 3731
36 B 69586403 AAPL 73420 1832
38 C 25247429
39 B 38043534 AMZN 57670 7363
38 B 3679159 AAPL 66946 9524
36 B 63179353 AMZN 20955 8244
39 C 5270954
38 C 86922514
39 C 68250466
38 C 79900673
36 B 54077284 MSFT 11306 7097
32 S 62701188 MSFT 64218 2907
39 S 73509191 GOOG 55933 7671
39 S 23265795 GOOG 67048 997
39 S 184260 GOOG 16413 5744
38 C 57201475
39 B 20962343 AAPL 24965 501
37 B 6627923 MSFT 37394 6595
39 C 76884492
39 S 99619679 AAPL 69705 1880
37 C 26455159
39 S 47597487 MSFT 54274 6248
38 S 85475543 MSFT 48503 8936
38 S 84334995 AAPL 57478 6384
39 C 54181844
34 S 63042801 GOOG 93991 3597
36 B 1815025 MSFT 4673 4579
39 C 79949165
38 B 4751084 AMZN 4867 7655
36 S 77570469 MSFT 69041 1975
37 C 72028411
36 S 25557256 AAPL 20003 6534
39 B 30176200 MSFT 24113 8937
39 C 65520234
36 B 53537172 AMZN 92866 7913
38 C 32376002
38 S 29874100 AAPL 51214 9314
38 B 84184731 AMZN 88330 1806
38 B 74645792 AMZN 55597 6861
37 C 77130868
38 S 16467304 AAPL 54394 5567
38 S 59667693 AMZN 26206 6396
38 C 4751084
36 C 80002238
36 B 77257270 AMZN 41298 3732
37 B 1709544 GOOG 82160 4284
38 S 20414788 AMZN 23218 2204
38 S 39624477 MSFT 32160 9282
37 S 22911218 AAPL 71473 7224
38 B 10735039 AMZN 87071 6722
38 C 74645792
37 C 1709544
38 S 77037609 AAPL 81486 7287
38 B 92204124 AAPL 50823 7542
32 C 62701188
38 C 39624477
36 C 16377066
35 C 83837991
38 B 87800909 MSFT 21626 1057
37 B 84242512 AAPL 62368 8526
38 C 25247429
37 C 64193228
35 C 20836108
37 S 96331070 AMZN 87369 964
38 C 57201475
38 S 76608080 AMZN 48511 9271
38 S 75775824 GOOG 93208 3372
38 C 38213986
37 C 52620774
38 C 86168286
37 B 46106025 AMZN 76489 7409
38 S 97180481 GOOG 30163 610
36 B 11285348 AAPL 41705 8107
38 B 25064659 MSFT 81342 8349
38 S 53480046 AAPL 76267 2616
37 S 14878082 MSFT 69420 9157
38 C 86168286
38 S 35783721 AAPL 48828 4161
37 B 90058312 AAPL 15852 8104
38 B 23857278 AMZN 5578 505
36 B 81118416 MSFT 22247 1206
36 C 80002238
37 B 20895989 AMZN 11123 5015
38 B 73202839 MSFT 18952 5620
38 C 40711141
38 S 32524644 MSFT 15597 5805
36 S 26955798 GOOG 44722 4945
38 S 74415581 MSFT 88132 4795
38 C 85475543
36 B 27238569 AAPL 25404 8988
38 B 51247489 AAPL 15176 6333
38 S 96337935 AMZN 63324 6611
38 S 69072096 GOOG 10767 9614
34 C 63042801
35 S 84640509 AMZN 54637 8450
38 S 3857322 AAPL 56105 1036
37 B 5837925 GOOG 44727 3030
36 B 84026545 AAPL 59801 1295
37 B 13808018 AAPL 11901 3159
38 B 40131642 MSFT 26858 8288
36 S 11048845 GOOG 41494 8726
38 B 59636419 MSFT 22846 9617
38 C 74415581
38 S 79734778 MSFT 97914 9739
38 S 20550321 AAPL 24125 5655
37 S 2859474 GOOG 81990 6878
36 S 5987172 AAPL 46750 6453
38 B 11530073 AMZN 61067 9778
37 C 1709544
36 S 32072943 AAPL 26519 3025
37 B 30270514 GOOG 74495 1443
38 B 57909006 MSFT 8388 8047
38 B 63330039 AAPL 63537 9398
38 S 84334169 AAPL 20921 7737
36 C 64601912
38 C 63330039
34 C 63042801
37 S 35768583 AAPL 54248 2353
37 C 64193228
38 S 67969047 MSFT 84379 1326
38 C 87800909
37 C 685956
38 S 43134650 AMZN 48814 8782
36 S 25202195 AMZN 29183 5952
35 C 84640509
34 B 80514611 AAPL 49337 8945
38 C 86168286
38 B 78486456 MSFT 46104 3027
38 C 3679159
38 C 25247429
37 S 26072498 MSFT 31756 36
38 C 84184731
37 C 64193228
37 C 90058312
36 B 25865706 GOOG 87239 1203
36 S 49195449 AMZN 56398 6076
38 B 98500722 GOOG 68634 2487
38 C 63330039
37 C 20895989
38 B 47931173 GOOG 79665 1412
38 B 29479754 MSFT 47067 1128
36 S 33666157 AAPL 2849 710
32 C 62701188
36 S 2918346 GOOG 58194 2014
37 C 90058312
38 B 73258412 MSFT 30529 7795
36 C 53537172
37 B 69237492 MSFT 80068 6270
33 B 99286255 GOOG 34310 2582
38 C 26928089
37 C 46106025
36 C 81118416
36 S 41254579 GOOG 17735 4879
37 B 59019654 AMZN 95200 24
34 B 48543793 MSFT 22510 8733
33 S 11356017 GOOG 76161 2141
37 S 20313897 GOOG 82355 9573
36 C 64601912
37 S 1470506 MSFT 44788 9934
37 C 35768583
37 S 42020623 GOOG 51921 272
37 C 97553118
